[2018-06-15 11:34:31 +0000] [5860] [ERROR] Exception in worker process
Traceback (most recent call last):
  File "/home/yamda/.virtualenvs/yamda_website/lib/python3.5/site-packages/gunicorn/arbiter.py", line 583, in spawn_worker
    worker.init_process()
  File "/home/yamda/.virtualenvs/yamda_website/lib/python3.5/site-packages/gunicorn/workers/base.py", line 129, in init_process
    self.load_wsgi()
  File "/home/yamda/.virtualenvs/yamda_website/lib/python3.5/site-packages/gunicorn/workers/base.py", line 138, in load_wsgi
    self.wsgi = self.app.wsgi()
  File "/home/yamda/.virtualenvs/yamda_website/lib/python3.5/site-packages/gunicorn/app/base.py", line 67, in wsgi
    self.callable = self.load()
  File "/home/yamda/.virtualenvs/yamda_website/lib/python3.5/site-packages/gunicorn/app/wsgiapp.py", line 52, in load
    return self.load_wsgiapp()
  File "/home/yamda/.virtualenvs/yamda_website/lib/python3.5/site-packages/gunicorn/app/wsgiapp.py", line 41, in load_wsgiapp
    return util.import_app(self.app_uri)
  File "/home/yamda/.virtualenvs/yamda_website/lib/python3.5/site-packages/gunicorn/util.py", line 350, in import_app
    __import__(module)
ImportError: No module named 'yamda'
[2018-06-15 11:34:32 +0000] [5861] [ERROR] Exception in worker process
Traceback (most recent call last):
  File "/home/yamda/.virtualenvs/yamda_website/lib/python3.5/site-packages/gunicorn/arbiter.py", line 583, in spawn_worker
    worker.init_process()
  File "/home/yamda/.virtualenvs/yamda_website/lib/python3.5/site-packages/gunicorn/workers/base.py", line 129, in init_process
    self.load_wsgi()
  File "/home/yamda/.virtualenvs/yamda_website/lib/python3.5/site-packages/gunicorn/workers/base.py", line 138, in load_wsgi
    self.wsgi = self.app.wsgi()
  File "/home/yamda/.virtualenvs/yamda_website/lib/python3.5/site-packages/gunicorn/app/base.py", line 67, in wsgi
    self.callable = self.load()
  File "/home/yamda/.virtualenvs/yamda_website/lib/python3.5/site-packages/gunicorn/app/wsgiapp.py", line 52, in load
    return self.load_wsgiapp()
  File "/home/yamda/.virtualenvs/yamda_website/lib/python3.5/site-packages/gunicorn/app/wsgiapp.py", line 41, in load_wsgiapp
    return util.import_app(self.app_uri)
  File "/home/yamda/.virtualenvs/yamda_website/lib/python3.5/site-packages/gunicorn/util.py", line 350, in import_app
    __import__(module)
ImportError: No module named 'yamda'
Traceback (most recent call last):
  File "/home/yamda/.virtualenvs/yamda_website/lib/python3.5/site-packages/gunicorn/arbiter.py", line 203, in run
    self.manage_workers()
  File "/home/yamda/.virtualenvs/yamda_website/lib/python3.5/site-packages/gunicorn/arbiter.py", line 545, in manage_workers
    self.spawn_workers()
  File "/home/yamda/.virtualenvs/yamda_website/lib/python3.5/site-packages/gunicorn/arbiter.py", line 617, in spawn_workers
    time.sleep(0.1 * random.random())
  File "/home/yamda/.virtualenvs/yamda_website/lib/python3.5/site-packages/gunicorn/arbiter.py", line 245, in handle_chld
    self.reap_workers()
  File "/home/yamda/.virtualenvs/yamda_website/lib/python3.5/site-packages/gunicorn/arbiter.py", line 525, in reap_workers
    raise HaltServer(reason, self.WORKER_BOOT_ERROR)
gunicorn.errors.HaltServer: <HaltServer 'Worker failed to boot.' 3>

During handling of the above exception, another exception occurred:

Traceback (most recent call last):
  File "/home/yamda/.virtualenvs/yamda_website/bin/gunicorn", line 11, in <module>
    sys.exit(run())
  File "/home/yamda/.virtualenvs/yamda_website/lib/python3.5/site-packages/gunicorn/app/wsgiapp.py", line 61, in run
    WSGIApplication("%(prog)s [OPTIONS] [APP_MODULE]").run()
  File "/home/yamda/.virtualenvs/yamda_website/lib/python3.5/site-packages/gunicorn/app/base.py", line 223, in run
    super(Application, self).run()
  File "/home/yamda/.virtualenvs/yamda_website/lib/python3.5/site-packages/gunicorn/app/base.py", line 72, in run
    Arbiter(self).run()
  File "/home/yamda/.virtualenvs/yamda_website/lib/python3.5/site-packages/gunicorn/arbiter.py", line 232, in run
    self.halt(reason=inst.reason, exit_status=inst.exit_status)
  File "/home/yamda/.virtualenvs/yamda_website/lib/python3.5/site-packages/gunicorn/arbiter.py", line 345, in halt
    self.stop()
  File "/home/yamda/.virtualenvs/yamda_website/lib/python3.5/site-packages/gunicorn/arbiter.py", line 393, in stop
    time.sleep(0.1)
  File "/home/yamda/.virtualenvs/yamda_website/lib/python3.5/site-packages/gunicorn/arbiter.py", line 245, in handle_chld
    self.reap_workers()
  File "/home/yamda/.virtualenvs/yamda_website/lib/python3.5/site-packages/gunicorn/arbiter.py", line 525, in reap_workers
    raise HaltServer(reason, self.WORKER_BOOT_ERROR)
gunicorn.errors.HaltServer: <HaltServer 'Worker failed to boot.' 3>
[2018-06-15 11:34:33 +0000] [5867] [ERROR] Exception in worker process
Traceback (most recent call last):
  File "/home/yamda/.virtualenvs/yamda_website/lib/python3.5/site-packages/gunicorn/arbiter.py", line 583, in spawn_worker
    worker.init_process()
  File "/home/yamda/.virtualenvs/yamda_website/lib/python3.5/site-packages/gunicorn/workers/base.py", line 129, in init_process
    self.load_wsgi()
  File "/home/yamda/.virtualenvs/yamda_website/lib/python3.5/site-packages/gunicorn/workers/base.py", line 138, in load_wsgi
    self.wsgi = self.app.wsgi()
  File "/home/yamda/.virtualenvs/yamda_website/lib/python3.5/site-packages/gunicorn/app/base.py", line 67, in wsgi
    self.callable = self.load()
  File "/home/yamda/.virtualenvs/yamda_website/lib/python3.5/site-packages/gunicorn/app/wsgiapp.py", line 52, in load
    return self.load_wsgiapp()
  File "/home/yamda/.virtualenvs/yamda_website/lib/python3.5/site-packages/gunicorn/app/wsgiapp.py", line 41, in load_wsgiapp
    return util.import_app(self.app_uri)
  File "/home/yamda/.virtualenvs/yamda_website/lib/python3.5/site-packages/gunicorn/util.py", line 350, in import_app
    __import__(module)
ImportError: No module named 'yamda'
[2018-06-15 11:34:33 +0000] [5868] [ERROR] Exception in worker process
Traceback (most recent call last):
  File "/home/yamda/.virtualenvs/yamda_website/lib/python3.5/site-packages/gunicorn/arbiter.py", line 583, in spawn_worker
    worker.init_process()
  File "/home/yamda/.virtualenvs/yamda_website/lib/python3.5/site-packages/gunicorn/workers/base.py", line 129, in init_process
    self.load_wsgi()
  File "/home/yamda/.virtualenvs/yamda_website/lib/python3.5/site-packages/gunicorn/workers/base.py", line 138, in load_wsgi
    self.wsgi = self.app.wsgi()
  File "/home/yamda/.virtualenvs/yamda_website/lib/python3.5/site-packages/gunicorn/app/base.py", line 67, in wsgi
    self.callable = self.load()
  File "/home/yamda/.virtualenvs/yamda_website/lib/python3.5/site-packages/gunicorn/app/wsgiapp.py", line 52, in load
    return self.load_wsgiapp()
  File "/home/yamda/.virtualenvs/yamda_website/lib/python3.5/site-packages/gunicorn/app/wsgiapp.py", line 41, in load_wsgiapp
    return util.import_app(self.app_uri)
  File "/home/yamda/.virtualenvs/yamda_website/lib/python3.5/site-packages/gunicorn/util.py", line 350, in import_app
    __import__(module)
ImportError: No module named 'yamda'
[2018-06-15 11:34:36 +0000] [5874] [ERROR] Exception in worker process
Traceback (most recent call last):
  File "/home/yamda/.virtualenvs/yamda_website/lib/python3.5/site-packages/gunicorn/arbiter.py", line 583, in spawn_worker
    worker.init_process()
  File "/home/yamda/.virtualenvs/yamda_website/lib/python3.5/site-packages/gunicorn/workers/base.py", line 129, in init_process
    self.load_wsgi()
  File "/home/yamda/.virtualenvs/yamda_website/lib/python3.5/site-packages/gunicorn/workers/base.py", line 138, in load_wsgi
    self.wsgi = self.app.wsgi()
  File "/home/yamda/.virtualenvs/yamda_website/lib/python3.5/site-packages/gunicorn/app/base.py", line 67, in wsgi
    self.callable = self.load()
  File "/home/yamda/.virtualenvs/yamda_website/lib/python3.5/site-packages/gunicorn/app/wsgiapp.py", line 52, in load
    return self.load_wsgiapp()
  File "/home/yamda/.virtualenvs/yamda_website/lib/python3.5/site-packages/gunicorn/app/wsgiapp.py", line 41, in load_wsgiapp
    return util.import_app(self.app_uri)
  File "/home/yamda/.virtualenvs/yamda_website/lib/python3.5/site-packages/gunicorn/util.py", line 350, in import_app
    __import__(module)
ImportError: No module named 'yamda'
[2018-06-15 11:34:36 +0000] [5875] [ERROR] Exception in worker process
Traceback (most recent call last):
  File "/home/yamda/.virtualenvs/yamda_website/lib/python3.5/site-packages/gunicorn/arbiter.py", line 583, in spawn_worker
    worker.init_process()
  File "/home/yamda/.virtualenvs/yamda_website/lib/python3.5/site-packages/gunicorn/workers/base.py", line 129, in init_process
    self.load_wsgi()
  File "/home/yamda/.virtualenvs/yamda_website/lib/python3.5/site-packages/gunicorn/workers/base.py", line 138, in load_wsgi
    self.wsgi = self.app.wsgi()
  File "/home/yamda/.virtualenvs/yamda_website/lib/python3.5/site-packages/gunicorn/app/base.py", line 67, in wsgi
    self.callable = self.load()
  File "/home/yamda/.virtualenvs/yamda_website/lib/python3.5/site-packages/gunicorn/app/wsgiapp.py", line 52, in load
    return self.load_wsgiapp()
  File "/home/yamda/.virtualenvs/yamda_website/lib/python3.5/site-packages/gunicorn/app/wsgiapp.py", line 41, in load_wsgiapp
    return util.import_app(self.app_uri)
  File "/home/yamda/.virtualenvs/yamda_website/lib/python3.5/site-packages/gunicorn/util.py", line 350, in import_app
    __import__(module)
ImportError: No module named 'yamda'
[2018-06-15 11:34:36 +0000] [5876] [ERROR] Exception in worker process
Traceback (most recent call last):
  File "/home/yamda/.virtualenvs/yamda_website/lib/python3.5/site-packages/gunicorn/arbiter.py", line 583, in spawn_worker
    worker.init_process()
  File "/home/yamda/.virtualenvs/yamda_website/lib/python3.5/site-packages/gunicorn/workers/base.py", line 129, in init_process
    self.load_wsgi()
  File "/home/yamda/.virtualenvs/yamda_website/lib/python3.5/site-packages/gunicorn/workers/base.py", line 138, in load_wsgi
    self.wsgi = self.app.wsgi()
  File "/home/yamda/.virtualenvs/yamda_website/lib/python3.5/site-packages/gunicorn/app/base.py", line 67, in wsgi
    self.callable = self.load()
  File "/home/yamda/.virtualenvs/yamda_website/lib/python3.5/site-packages/gunicorn/app/wsgiapp.py", line 52, in load
    return self.load_wsgiapp()
  File "/home/yamda/.virtualenvs/yamda_website/lib/python3.5/site-packages/gunicorn/app/wsgiapp.py", line 41, in load_wsgiapp
    return util.import_app(self.app_uri)
  File "/home/yamda/.virtualenvs/yamda_website/lib/python3.5/site-packages/gunicorn/util.py", line 350, in import_app
    __import__(module)
ImportError: No module named 'yamda'
Traceback (most recent call last):
  File "/home/yamda/.virtualenvs/yamda_website/lib/python3.5/site-packages/gunicorn/arbiter.py", line 203, in run
    self.manage_workers()
  File "/home/yamda/.virtualenvs/yamda_website/lib/python3.5/site-packages/gunicorn/arbiter.py", line 545, in manage_workers
    self.spawn_workers()
  File "/home/yamda/.virtualenvs/yamda_website/lib/python3.5/site-packages/gunicorn/arbiter.py", line 617, in spawn_workers
    time.sleep(0.1 * random.random())
  File "/home/yamda/.virtualenvs/yamda_website/lib/python3.5/site-packages/gunicorn/arbiter.py", line 245, in handle_chld
    self.reap_workers()
  File "/home/yamda/.virtualenvs/yamda_website/lib/python3.5/site-packages/gunicorn/arbiter.py", line 525, in reap_workers
    raise HaltServer(reason, self.WORKER_BOOT_ERROR)
gunicorn.errors.HaltServer: <HaltServer 'Worker failed to boot.' 3>

During handling of the above exception, another exception occurred:

Traceback (most recent call last):
  File "/home/yamda/.virtualenvs/yamda_website/bin/gunicorn", line 11, in <module>
    sys.exit(run())
  File "/home/yamda/.virtualenvs/yamda_website/lib/python3.5/site-packages/gunicorn/app/wsgiapp.py", line 61, in run
    WSGIApplication("%(prog)s [OPTIONS] [APP_MODULE]").run()
  File "/home/yamda/.virtualenvs/yamda_website/lib/python3.5/site-packages/gunicorn/app/base.py", line 223, in run
    super(Application, self).run()
  File "/home/yamda/.virtualenvs/yamda_website/lib/python3.5/site-packages/gunicorn/app/base.py", line 72, in run
    Arbiter(self).run()
  File "/home/yamda/.virtualenvs/yamda_website/lib/python3.5/site-packages/gunicorn/arbiter.py", line 232, in run
    self.halt(reason=inst.reason, exit_status=inst.exit_status)
  File "/home/yamda/.virtualenvs/yamda_website/lib/python3.5/site-packages/gunicorn/arbiter.py", line 345, in halt
    self.stop()
  File "/home/yamda/.virtualenvs/yamda_website/lib/python3.5/site-packages/gunicorn/arbiter.py", line 393, in stop
    time.sleep(0.1)
  File "/home/yamda/.virtualenvs/yamda_website/lib/python3.5/site-packages/gunicorn/arbiter.py", line 245, in handle_chld
    self.reap_workers()
  File "/home/yamda/.virtualenvs/yamda_website/lib/python3.5/site-packages/gunicorn/arbiter.py", line 525, in reap_workers
    raise HaltServer(reason, self.WORKER_BOOT_ERROR)
gunicorn.errors.HaltServer: <HaltServer 'Worker failed to boot.' 3>
[2018-06-15 11:34:39 +0000] [5883] [ERROR] Exception in worker process
Traceback (most recent call last):
  File "/home/yamda/.virtualenvs/yamda_website/lib/python3.5/site-packages/gunicorn/arbiter.py", line 583, in spawn_worker
    worker.init_process()
  File "/home/yamda/.virtualenvs/yamda_website/lib/python3.5/site-packages/gunicorn/workers/base.py", line 129, in init_process
    self.load_wsgi()
  File "/home/yamda/.virtualenvs/yamda_website/lib/python3.5/site-packages/gunicorn/workers/base.py", line 138, in load_wsgi
    self.wsgi = self.app.wsgi()
  File "/home/yamda/.virtualenvs/yamda_website/lib/python3.5/site-packages/gunicorn/app/base.py", line 67, in wsgi
    self.callable = self.load()
  File "/home/yamda/.virtualenvs/yamda_website/lib/python3.5/site-packages/gunicorn/app/wsgiapp.py", line 52, in load
    return self.load_wsgiapp()
  File "/home/yamda/.virtualenvs/yamda_website/lib/python3.5/site-packages/gunicorn/app/wsgiapp.py", line 41, in load_wsgiapp
    return util.import_app(self.app_uri)
  File "/home/yamda/.virtualenvs/yamda_website/lib/python3.5/site-packages/gunicorn/util.py", line 350, in import_app
    __import__(module)
ImportError: No module named 'yamda'
[2018-06-15 11:44:56 +0000] [5965] [ERROR] Exception in worker process
Traceback (most recent call last):
  File "/home/yamda/.virtualenvs/yamda_website/lib/python3.5/site-packages/gunicorn/arbiter.py", line 583, in spawn_worker
    worker.init_process()
  File "/home/yamda/.virtualenvs/yamda_website/lib/python3.5/site-packages/gunicorn/workers/base.py", line 129, in init_process
    self.load_wsgi()
  File "/home/yamda/.virtualenvs/yamda_website/lib/python3.5/site-packages/gunicorn/workers/base.py", line 138, in load_wsgi
    self.wsgi = self.app.wsgi()
  File "/home/yamda/.virtualenvs/yamda_website/lib/python3.5/site-packages/gunicorn/app/base.py", line 67, in wsgi
    self.callable = self.load()
  File "/home/yamda/.virtualenvs/yamda_website/lib/python3.5/site-packages/gunicorn/app/wsgiapp.py", line 52, in load
    return self.load_wsgiapp()
  File "/home/yamda/.virtualenvs/yamda_website/lib/python3.5/site-packages/gunicorn/app/wsgiapp.py", line 41, in load_wsgiapp
    return util.import_app(self.app_uri)
  File "/home/yamda/.virtualenvs/yamda_website/lib/python3.5/site-packages/gunicorn/util.py", line 350, in import_app
    __import__(module)
ImportError: No module named 'yamda'
[2018-06-15 11:44:56 +0000] [5966] [ERROR] Exception in worker process
Traceback (most recent call last):
  File "/home/yamda/.virtualenvs/yamda_website/lib/python3.5/site-packages/gunicorn/arbiter.py", line 583, in spawn_worker
    worker.init_process()
  File "/home/yamda/.virtualenvs/yamda_website/lib/python3.5/site-packages/gunicorn/workers/base.py", line 129, in init_process
    self.load_wsgi()
  File "/home/yamda/.virtualenvs/yamda_website/lib/python3.5/site-packages/gunicorn/workers/base.py", line 138, in load_wsgi
    self.wsgi = self.app.wsgi()
  File "/home/yamda/.virtualenvs/yamda_website/lib/python3.5/site-packages/gunicorn/app/base.py", line 67, in wsgi
    self.callable = self.load()
  File "/home/yamda/.virtualenvs/yamda_website/lib/python3.5/site-packages/gunicorn/app/wsgiapp.py", line 52, in load
    return self.load_wsgiapp()
  File "/home/yamda/.virtualenvs/yamda_website/lib/python3.5/site-packages/gunicorn/app/wsgiapp.py", line 41, in load_wsgiapp
    return util.import_app(self.app_uri)
  File "/home/yamda/.virtualenvs/yamda_website/lib/python3.5/site-packages/gunicorn/util.py", line 350, in import_app
    __import__(module)
ImportError: No module named 'yamda'
Traceback (most recent call last):
  File "/home/yamda/.virtualenvs/yamda_website/lib/python3.5/site-packages/gunicorn/arbiter.py", line 203, in run
    self.manage_workers()
  File "/home/yamda/.virtualenvs/yamda_website/lib/python3.5/site-packages/gunicorn/arbiter.py", line 545, in manage_workers
    self.spawn_workers()
  File "/home/yamda/.virtualenvs/yamda_website/lib/python3.5/site-packages/gunicorn/arbiter.py", line 617, in spawn_workers
    time.sleep(0.1 * random.random())
  File "/home/yamda/.virtualenvs/yamda_website/lib/python3.5/site-packages/gunicorn/arbiter.py", line 245, in handle_chld
    self.reap_workers()
  File "/home/yamda/.virtualenvs/yamda_website/lib/python3.5/site-packages/gunicorn/arbiter.py", line 525, in reap_workers
    raise HaltServer(reason, self.WORKER_BOOT_ERROR)
gunicorn.errors.HaltServer: <HaltServer 'Worker failed to boot.' 3>

During handling of the above exception, another exception occurred:

Traceback (most recent call last):
  File "/home/yamda/.virtualenvs/yamda_website/bin/gunicorn", line 11, in <module>
    sys.exit(run())
  File "/home/yamda/.virtualenvs/yamda_website/lib/python3.5/site-packages/gunicorn/app/wsgiapp.py", line 61, in run
    WSGIApplication("%(prog)s [OPTIONS] [APP_MODULE]").run()
  File "/home/yamda/.virtualenvs/yamda_website/lib/python3.5/site-packages/gunicorn/app/base.py", line 223, in run
    super(Application, self).run()
  File "/home/yamda/.virtualenvs/yamda_website/lib/python3.5/site-packages/gunicorn/app/base.py", line 72, in run
    Arbiter(self).run()
  File "/home/yamda/.virtualenvs/yamda_website/lib/python3.5/site-packages/gunicorn/arbiter.py", line 232, in run
    self.halt(reason=inst.reason, exit_status=inst.exit_status)
  File "/home/yamda/.virtualenvs/yamda_website/lib/python3.5/site-packages/gunicorn/arbiter.py", line 345, in halt
    self.stop()
  File "/home/yamda/.virtualenvs/yamda_website/lib/python3.5/site-packages/gunicorn/arbiter.py", line 393, in stop
    time.sleep(0.1)
  File "/home/yamda/.virtualenvs/yamda_website/lib/python3.5/site-packages/gunicorn/arbiter.py", line 245, in handle_chld
    self.reap_workers()
  File "/home/yamda/.virtualenvs/yamda_website/lib/python3.5/site-packages/gunicorn/arbiter.py", line 525, in reap_workers
    raise HaltServer(reason, self.WORKER_BOOT_ERROR)
gunicorn.errors.HaltServer: <HaltServer 'Worker failed to boot.' 3>
[2018-06-15 11:44:58 +0000] [5972] [ERROR] Exception in worker process
Traceback (most recent call last):
  File "/home/yamda/.virtualenvs/yamda_website/lib/python3.5/site-packages/gunicorn/arbiter.py", line 583, in spawn_worker
    worker.init_process()
  File "/home/yamda/.virtualenvs/yamda_website/lib/python3.5/site-packages/gunicorn/workers/base.py", line 129, in init_process
    self.load_wsgi()
  File "/home/yamda/.virtualenvs/yamda_website/lib/python3.5/site-packages/gunicorn/workers/base.py", line 138, in load_wsgi
    self.wsgi = self.app.wsgi()
  File "/home/yamda/.virtualenvs/yamda_website/lib/python3.5/site-packages/gunicorn/app/base.py", line 67, in wsgi
    self.callable = self.load()
  File "/home/yamda/.virtualenvs/yamda_website/lib/python3.5/site-packages/gunicorn/app/wsgiapp.py", line 52, in load
    return self.load_wsgiapp()
  File "/home/yamda/.virtualenvs/yamda_website/lib/python3.5/site-packages/gunicorn/app/wsgiapp.py", line 41, in load_wsgiapp
    return util.import_app(self.app_uri)
  File "/home/yamda/.virtualenvs/yamda_website/lib/python3.5/site-packages/gunicorn/util.py", line 350, in import_app
    __import__(module)
ImportError: No module named 'yamda'
[2018-06-15 11:45:00 +0000] [5978] [ERROR] Exception in worker process
Traceback (most recent call last):
  File "/home/yamda/.virtualenvs/yamda_website/lib/python3.5/site-packages/gunicorn/arbiter.py", line 583, in spawn_worker
    worker.init_process()
  File "/home/yamda/.virtualenvs/yamda_website/lib/python3.5/site-packages/gunicorn/workers/base.py", line 129, in init_process
    self.load_wsgi()
  File "/home/yamda/.virtualenvs/yamda_website/lib/python3.5/site-packages/gunicorn/workers/base.py", line 138, in load_wsgi
    self.wsgi = self.app.wsgi()
  File "/home/yamda/.virtualenvs/yamda_website/lib/python3.5/site-packages/gunicorn/app/base.py", line 67, in wsgi
    self.callable = self.load()
  File "/home/yamda/.virtualenvs/yamda_website/lib/python3.5/site-packages/gunicorn/app/wsgiapp.py", line 52, in load
    return self.load_wsgiapp()
  File "/home/yamda/.virtualenvs/yamda_website/lib/python3.5/site-packages/gunicorn/app/wsgiapp.py", line 41, in load_wsgiapp
    return util.import_app(self.app_uri)
  File "/home/yamda/.virtualenvs/yamda_website/lib/python3.5/site-packages/gunicorn/util.py", line 350, in import_app
    __import__(module)
ImportError: No module named 'yamda'
[2018-06-15 11:45:00 +0000] [5979] [ERROR] Exception in worker process
Traceback (most recent call last):
  File "/home/yamda/.virtualenvs/yamda_website/lib/python3.5/site-packages/gunicorn/arbiter.py", line 583, in spawn_worker
    worker.init_process()
  File "/home/yamda/.virtualenvs/yamda_website/lib/python3.5/site-packages/gunicorn/workers/base.py", line 129, in init_process
    self.load_wsgi()
  File "/home/yamda/.virtualenvs/yamda_website/lib/python3.5/site-packages/gunicorn/workers/base.py", line 138, in load_wsgi
    self.wsgi = self.app.wsgi()
  File "/home/yamda/.virtualenvs/yamda_website/lib/python3.5/site-packages/gunicorn/app/base.py", line 67, in wsgi
    self.callable = self.load()
  File "/home/yamda/.virtualenvs/yamda_website/lib/python3.5/site-packages/gunicorn/app/wsgiapp.py", line 52, in load
    return self.load_wsgiapp()
  File "/home/yamda/.virtualenvs/yamda_website/lib/python3.5/site-packages/gunicorn/app/wsgiapp.py", line 41, in load_wsgiapp
    return util.import_app(self.app_uri)
  File "/home/yamda/.virtualenvs/yamda_website/lib/python3.5/site-packages/gunicorn/util.py", line 350, in import_app
    __import__(module)
ImportError: No module named 'yamda'
[2018-06-15 11:45:00 +0000] [5980] [ERROR] Exception in worker process
Traceback (most recent call last):
  File "/home/yamda/.virtualenvs/yamda_website/lib/python3.5/site-packages/gunicorn/arbiter.py", line 583, in spawn_worker
    worker.init_process()
  File "/home/yamda/.virtualenvs/yamda_website/lib/python3.5/site-packages/gunicorn/workers/base.py", line 129, in init_process
    self.load_wsgi()
  File "/home/yamda/.virtualenvs/yamda_website/lib/python3.5/site-packages/gunicorn/workers/base.py", line 138, in load_wsgi
    self.wsgi = self.app.wsgi()
  File "/home/yamda/.virtualenvs/yamda_website/lib/python3.5/site-packages/gunicorn/app/base.py", line 67, in wsgi
    self.callable = self.load()
  File "/home/yamda/.virtualenvs/yamda_website/lib/python3.5/site-packages/gunicorn/app/wsgiapp.py", line 52, in load
    return self.load_wsgiapp()
  File "/home/yamda/.virtualenvs/yamda_website/lib/python3.5/site-packages/gunicorn/app/wsgiapp.py", line 41, in load_wsgiapp
    return util.import_app(self.app_uri)
  File "/home/yamda/.virtualenvs/yamda_website/lib/python3.5/site-packages/gunicorn/util.py", line 350, in import_app
    __import__(module)
ImportError: No module named 'yamda'
[2018-06-15 11:45:04 +0000] [5991] [ERROR] Exception in worker process
Traceback (most recent call last):
  File "/home/yamda/.virtualenvs/yamda_website/lib/python3.5/site-packages/gunicorn/arbiter.py", line 583, in spawn_worker
    worker.init_process()
  File "/home/yamda/.virtualenvs/yamda_website/lib/python3.5/site-packages/gunicorn/workers/base.py", line 129, in init_process
    self.load_wsgi()
  File "/home/yamda/.virtualenvs/yamda_website/lib/python3.5/site-packages/gunicorn/workers/base.py", line 138, in load_wsgi
    self.wsgi = self.app.wsgi()
  File "/home/yamda/.virtualenvs/yamda_website/lib/python3.5/site-packages/gunicorn/app/base.py", line 67, in wsgi
    self.callable = self.load()
  File "/home/yamda/.virtualenvs/yamda_website/lib/python3.5/site-packages/gunicorn/app/wsgiapp.py", line 52, in load
    return self.load_wsgiapp()
  File "/home/yamda/.virtualenvs/yamda_website/lib/python3.5/site-packages/gunicorn/app/wsgiapp.py", line 41, in load_wsgiapp
    return util.import_app(self.app_uri)
  File "/home/yamda/.virtualenvs/yamda_website/lib/python3.5/site-packages/gunicorn/util.py", line 350, in import_app
    __import__(module)
ImportError: No module named 'yamda'
[2018-06-15 11:45:04 +0000] [5992] [ERROR] Exception in worker process
Traceback (most recent call last):
  File "/home/yamda/.virtualenvs/yamda_website/lib/python3.5/site-packages/gunicorn/arbiter.py", line 583, in spawn_worker
    worker.init_process()
  File "/home/yamda/.virtualenvs/yamda_website/lib/python3.5/site-packages/gunicorn/workers/base.py", line 129, in init_process
    self.load_wsgi()
  File "/home/yamda/.virtualenvs/yamda_website/lib/python3.5/site-packages/gunicorn/workers/base.py", line 138, in load_wsgi
    self.wsgi = self.app.wsgi()
  File "/home/yamda/.virtualenvs/yamda_website/lib/python3.5/site-packages/gunicorn/app/base.py", line 67, in wsgi
    self.callable = self.load()
  File "/home/yamda/.virtualenvs/yamda_website/lib/python3.5/site-packages/gunicorn/app/wsgiapp.py", line 52, in load
    return self.load_wsgiapp()
  File "/home/yamda/.virtualenvs/yamda_website/lib/python3.5/site-packages/gunicorn/app/wsgiapp.py", line 41, in load_wsgiapp
    return util.import_app(self.app_uri)
  File "/home/yamda/.virtualenvs/yamda_website/lib/python3.5/site-packages/gunicorn/util.py", line 350, in import_app
    __import__(module)
ImportError: No module named 'yamda'
[2018-06-15 11:45:04 +0000] [5993] [ERROR] Exception in worker process
Traceback (most recent call last):
  File "/home/yamda/.virtualenvs/yamda_website/lib/python3.5/site-packages/gunicorn/arbiter.py", line 583, in spawn_worker
    worker.init_process()
  File "/home/yamda/.virtualenvs/yamda_website/lib/python3.5/site-packages/gunicorn/workers/base.py", line 129, in init_process
    self.load_wsgi()
  File "/home/yamda/.virtualenvs/yamda_website/lib/python3.5/site-packages/gunicorn/workers/base.py", line 138, in load_wsgi
    self.wsgi = self.app.wsgi()
  File "/home/yamda/.virtualenvs/yamda_website/lib/python3.5/site-packages/gunicorn/app/base.py", line 67, in wsgi
    self.callable = self.load()
  File "/home/yamda/.virtualenvs/yamda_website/lib/python3.5/site-packages/gunicorn/app/wsgiapp.py", line 52, in load
    return self.load_wsgiapp()
  File "/home/yamda/.virtualenvs/yamda_website/lib/python3.5/site-packages/gunicorn/app/wsgiapp.py", line 41, in load_wsgiapp
    return util.import_app(self.app_uri)
  File "/home/yamda/.virtualenvs/yamda_website/lib/python3.5/site-packages/gunicorn/util.py", line 350, in import_app
    __import__(module)
ImportError: No module named 'yamda'
Traceback (most recent call last):
  File "/home/yamda/.virtualenvs/yamda_website/bin/gunicorn", line 7, in <module>
    from gunicorn.app.wsgiapp import run
  File "/home/yamda/.virtualenvs/yamda_website/lib/python3.5/site-packages/gunicorn/app/wsgiapp.py", line 41
    print('*****************')
                             ^
TabError: inconsistent use of tabs and spaces in indentation
Traceback (most recent call last):
  File "/home/yamda/.virtualenvs/yamda_website/bin/gunicorn", line 7, in <module>
    from gunicorn.app.wsgiapp import run
  File "/home/yamda/.virtualenvs/yamda_website/lib/python3.5/site-packages/gunicorn/app/wsgiapp.py", line 41
    print('*****************')
                             ^
TabError: inconsistent use of tabs and spaces in indentation
Traceback (most recent call last):
  File "/home/yamda/.virtualenvs/yamda_website/bin/gunicorn", line 7, in <module>
    from gunicorn.app.wsgiapp import run
  File "/home/yamda/.virtualenvs/yamda_website/lib/python3.5/site-packages/gunicorn/app/wsgiapp.py", line 41
    print('*****************')
                             ^
TabError: inconsistent use of tabs and spaces in indentation
Traceback (most recent call last):
  File "/home/yamda/.virtualenvs/yamda_website/bin/gunicorn", line 7, in <module>
    from gunicorn.app.wsgiapp import run
  File "/home/yamda/.virtualenvs/yamda_website/lib/python3.5/site-packages/gunicorn/app/wsgiapp.py", line 41
    print('*****************')
                             ^
TabError: inconsistent use of tabs and spaces in indentation
[2018-06-15 11:54:44 +0000] [6104] [ERROR] Exception in worker process
Traceback (most recent call last):
  File "/home/yamda/.virtualenvs/yamda_website/lib/python3.5/site-packages/gunicorn/arbiter.py", line 583, in spawn_worker
    worker.init_process()
  File "/home/yamda/.virtualenvs/yamda_website/lib/python3.5/site-packages/gunicorn/workers/base.py", line 129, in init_process
    self.load_wsgi()
  File "/home/yamda/.virtualenvs/yamda_website/lib/python3.5/site-packages/gunicorn/workers/base.py", line 138, in load_wsgi
    self.wsgi = self.app.wsgi()
  File "/home/yamda/.virtualenvs/yamda_website/lib/python3.5/site-packages/gunicorn/app/base.py", line 67, in wsgi
    self.callable = self.load()
  File "/home/yamda/.virtualenvs/yamda_website/lib/python3.5/site-packages/gunicorn/app/wsgiapp.py", line 54, in load
    return self.load_wsgiapp()
  File "/home/yamda/.virtualenvs/yamda_website/lib/python3.5/site-packages/gunicorn/app/wsgiapp.py", line 43, in load_wsgiapp
    return util.import_app(self.app_uri)
  File "/home/yamda/.virtualenvs/yamda_website/lib/python3.5/site-packages/gunicorn/util.py", line 350, in import_app
    __import__(module)
ImportError: No module named 'yamda'
*****************
yamda.wsgi:application
[2018-06-15 11:54:44 +0000] [6105] [ERROR] Exception in worker process
Traceback (most recent call last):
  File "/home/yamda/.virtualenvs/yamda_website/lib/python3.5/site-packages/gunicorn/arbiter.py", line 583, in spawn_worker
    worker.init_process()
  File "/home/yamda/.virtualenvs/yamda_website/lib/python3.5/site-packages/gunicorn/workers/base.py", line 129, in init_process
    self.load_wsgi()
  File "/home/yamda/.virtualenvs/yamda_website/lib/python3.5/site-packages/gunicorn/workers/base.py", line 138, in load_wsgi
    self.wsgi = self.app.wsgi()
  File "/home/yamda/.virtualenvs/yamda_website/lib/python3.5/site-packages/gunicorn/app/base.py", line 67, in wsgi
    self.callable = self.load()
  File "/home/yamda/.virtualenvs/yamda_website/lib/python3.5/site-packages/gunicorn/app/wsgiapp.py", line 54, in load
    return self.load_wsgiapp()
  File "/home/yamda/.virtualenvs/yamda_website/lib/python3.5/site-packages/gunicorn/app/wsgiapp.py", line 43, in load_wsgiapp
    return util.import_app(self.app_uri)
  File "/home/yamda/.virtualenvs/yamda_website/lib/python3.5/site-packages/gunicorn/util.py", line 350, in import_app
    __import__(module)
ImportError: No module named 'yamda'
*****************
yamda.wsgi:application
[2018-06-15 11:54:44 +0000] [6106] [ERROR] Exception in worker process
Traceback (most recent call last):
  File "/home/yamda/.virtualenvs/yamda_website/lib/python3.5/site-packages/gunicorn/arbiter.py", line 583, in spawn_worker
    worker.init_process()
  File "/home/yamda/.virtualenvs/yamda_website/lib/python3.5/site-packages/gunicorn/workers/base.py", line 129, in init_process
    self.load_wsgi()
  File "/home/yamda/.virtualenvs/yamda_website/lib/python3.5/site-packages/gunicorn/workers/base.py", line 138, in load_wsgi
    self.wsgi = self.app.wsgi()
  File "/home/yamda/.virtualenvs/yamda_website/lib/python3.5/site-packages/gunicorn/app/base.py", line 67, in wsgi
    self.callable = self.load()
  File "/home/yamda/.virtualenvs/yamda_website/lib/python3.5/site-packages/gunicorn/app/wsgiapp.py", line 54, in load
    return self.load_wsgiapp()
  File "/home/yamda/.virtualenvs/yamda_website/lib/python3.5/site-packages/gunicorn/app/wsgiapp.py", line 43, in load_wsgiapp
    return util.import_app(self.app_uri)
  File "/home/yamda/.virtualenvs/yamda_website/lib/python3.5/site-packages/gunicorn/util.py", line 350, in import_app
    __import__(module)
ImportError: No module named 'yamda'
*****************
yamda.wsgi:application
[2018-06-15 11:54:45 +0000] [6112] [ERROR] Exception in worker process
Traceback (most recent call last):
  File "/home/yamda/.virtualenvs/yamda_website/lib/python3.5/site-packages/gunicorn/arbiter.py", line 583, in spawn_worker
    worker.init_process()
  File "/home/yamda/.virtualenvs/yamda_website/lib/python3.5/site-packages/gunicorn/workers/base.py", line 129, in init_process
    self.load_wsgi()
  File "/home/yamda/.virtualenvs/yamda_website/lib/python3.5/site-packages/gunicorn/workers/base.py", line 138, in load_wsgi
    self.wsgi = self.app.wsgi()
  File "/home/yamda/.virtualenvs/yamda_website/lib/python3.5/site-packages/gunicorn/app/base.py", line 67, in wsgi
    self.callable = self.load()
  File "/home/yamda/.virtualenvs/yamda_website/lib/python3.5/site-packages/gunicorn/app/wsgiapp.py", line 54, in load
    return self.load_wsgiapp()
  File "/home/yamda/.virtualenvs/yamda_website/lib/python3.5/site-packages/gunicorn/app/wsgiapp.py", line 43, in load_wsgiapp
    return util.import_app(self.app_uri)
  File "/home/yamda/.virtualenvs/yamda_website/lib/python3.5/site-packages/gunicorn/util.py", line 350, in import_app
    __import__(module)
ImportError: No module named 'yamda'
*****************
yamda.wsgi:application
[2018-06-15 11:54:45 +0000] [6113] [ERROR] Exception in worker process
Traceback (most recent call last):
  File "/home/yamda/.virtualenvs/yamda_website/lib/python3.5/site-packages/gunicorn/arbiter.py", line 583, in spawn_worker
    worker.init_process()
  File "/home/yamda/.virtualenvs/yamda_website/lib/python3.5/site-packages/gunicorn/workers/base.py", line 129, in init_process
    self.load_wsgi()
  File "/home/yamda/.virtualenvs/yamda_website/lib/python3.5/site-packages/gunicorn/workers/base.py", line 138, in load_wsgi
    self.wsgi = self.app.wsgi()
  File "/home/yamda/.virtualenvs/yamda_website/lib/python3.5/site-packages/gunicorn/app/base.py", line 67, in wsgi
    self.callable = self.load()
  File "/home/yamda/.virtualenvs/yamda_website/lib/python3.5/site-packages/gunicorn/app/wsgiapp.py", line 54, in load
    return self.load_wsgiapp()
  File "/home/yamda/.virtualenvs/yamda_website/lib/python3.5/site-packages/gunicorn/app/wsgiapp.py", line 43, in load_wsgiapp
    return util.import_app(self.app_uri)
  File "/home/yamda/.virtualenvs/yamda_website/lib/python3.5/site-packages/gunicorn/util.py", line 350, in import_app
    __import__(module)
ImportError: No module named 'yamda'
*****************
yamda.wsgi:application
[2018-06-15 11:54:45 +0000] [6114] [ERROR] Exception in worker process
Traceback (most recent call last):
  File "/home/yamda/.virtualenvs/yamda_website/lib/python3.5/site-packages/gunicorn/arbiter.py", line 583, in spawn_worker
    worker.init_process()
  File "/home/yamda/.virtualenvs/yamda_website/lib/python3.5/site-packages/gunicorn/workers/base.py", line 129, in init_process
    self.load_wsgi()
  File "/home/yamda/.virtualenvs/yamda_website/lib/python3.5/site-packages/gunicorn/workers/base.py", line 138, in load_wsgi
    self.wsgi = self.app.wsgi()
  File "/home/yamda/.virtualenvs/yamda_website/lib/python3.5/site-packages/gunicorn/app/base.py", line 67, in wsgi
    self.callable = self.load()
  File "/home/yamda/.virtualenvs/yamda_website/lib/python3.5/site-packages/gunicorn/app/wsgiapp.py", line 54, in load
    return self.load_wsgiapp()
  File "/home/yamda/.virtualenvs/yamda_website/lib/python3.5/site-packages/gunicorn/app/wsgiapp.py", line 43, in load_wsgiapp
    return util.import_app(self.app_uri)
  File "/home/yamda/.virtualenvs/yamda_website/lib/python3.5/site-packages/gunicorn/util.py", line 350, in import_app
    __import__(module)
ImportError: No module named 'yamda'
*****************
yamda.wsgi:application
[2018-06-15 11:54:48 +0000] [6121] [ERROR] Exception in worker process
Traceback (most recent call last):
  File "/home/yamda/.virtualenvs/yamda_website/lib/python3.5/site-packages/gunicorn/arbiter.py", line 583, in spawn_worker
    worker.init_process()
  File "/home/yamda/.virtualenvs/yamda_website/lib/python3.5/site-packages/gunicorn/workers/base.py", line 129, in init_process
    self.load_wsgi()
  File "/home/yamda/.virtualenvs/yamda_website/lib/python3.5/site-packages/gunicorn/workers/base.py", line 138, in load_wsgi
    self.wsgi = self.app.wsgi()
  File "/home/yamda/.virtualenvs/yamda_website/lib/python3.5/site-packages/gunicorn/app/base.py", line 67, in wsgi
    self.callable = self.load()
  File "/home/yamda/.virtualenvs/yamda_website/lib/python3.5/site-packages/gunicorn/app/wsgiapp.py", line 54, in load
    return self.load_wsgiapp()
  File "/home/yamda/.virtualenvs/yamda_website/lib/python3.5/site-packages/gunicorn/app/wsgiapp.py", line 43, in load_wsgiapp
    return util.import_app(self.app_uri)
  File "/home/yamda/.virtualenvs/yamda_website/lib/python3.5/site-packages/gunicorn/util.py", line 350, in import_app
    __import__(module)
ImportError: No module named 'yamda'
*****************
yamda.wsgi:application
[2018-06-15 11:54:48 +0000] [6122] [ERROR] Exception in worker process
Traceback (most recent call last):
  File "/home/yamda/.virtualenvs/yamda_website/lib/python3.5/site-packages/gunicorn/arbiter.py", line 583, in spawn_worker
    worker.init_process()
  File "/home/yamda/.virtualenvs/yamda_website/lib/python3.5/site-packages/gunicorn/workers/base.py", line 129, in init_process
    self.load_wsgi()
  File "/home/yamda/.virtualenvs/yamda_website/lib/python3.5/site-packages/gunicorn/workers/base.py", line 138, in load_wsgi
    self.wsgi = self.app.wsgi()
  File "/home/yamda/.virtualenvs/yamda_website/lib/python3.5/site-packages/gunicorn/app/base.py", line 67, in wsgi
    self.callable = self.load()
  File "/home/yamda/.virtualenvs/yamda_website/lib/python3.5/site-packages/gunicorn/app/wsgiapp.py", line 54, in load
    return self.load_wsgiapp()
  File "/home/yamda/.virtualenvs/yamda_website/lib/python3.5/site-packages/gunicorn/app/wsgiapp.py", line 43, in load_wsgiapp
    return util.import_app(self.app_uri)
  File "/home/yamda/.virtualenvs/yamda_website/lib/python3.5/site-packages/gunicorn/util.py", line 350, in import_app
    __import__(module)
ImportError: No module named 'yamda'
*****************
yamda.wsgi:application
[2018-06-15 11:54:48 +0000] [6123] [ERROR] Exception in worker process
Traceback (most recent call last):
  File "/home/yamda/.virtualenvs/yamda_website/lib/python3.5/site-packages/gunicorn/arbiter.py", line 583, in spawn_worker
    worker.init_process()
  File "/home/yamda/.virtualenvs/yamda_website/lib/python3.5/site-packages/gunicorn/workers/base.py", line 129, in init_process
    self.load_wsgi()
  File "/home/yamda/.virtualenvs/yamda_website/lib/python3.5/site-packages/gunicorn/workers/base.py", line 138, in load_wsgi
    self.wsgi = self.app.wsgi()
  File "/home/yamda/.virtualenvs/yamda_website/lib/python3.5/site-packages/gunicorn/app/base.py", line 67, in wsgi
    self.callable = self.load()
  File "/home/yamda/.virtualenvs/yamda_website/lib/python3.5/site-packages/gunicorn/app/wsgiapp.py", line 54, in load
    return self.load_wsgiapp()
  File "/home/yamda/.virtualenvs/yamda_website/lib/python3.5/site-packages/gunicorn/app/wsgiapp.py", line 43, in load_wsgiapp
    return util.import_app(self.app_uri)
  File "/home/yamda/.virtualenvs/yamda_website/lib/python3.5/site-packages/gunicorn/util.py", line 350, in import_app
    __import__(module)
ImportError: No module named 'yamda'
*****************
yamda.wsgi:application
[2018-06-15 11:54:52 +0000] [6130] [ERROR] Exception in worker process
Traceback (most recent call last):
  File "/home/yamda/.virtualenvs/yamda_website/lib/python3.5/site-packages/gunicorn/arbiter.py", line 583, in spawn_worker
    worker.init_process()
  File "/home/yamda/.virtualenvs/yamda_website/lib/python3.5/site-packages/gunicorn/workers/base.py", line 129, in init_process
    self.load_wsgi()
  File "/home/yamda/.virtualenvs/yamda_website/lib/python3.5/site-packages/gunicorn/workers/base.py", line 138, in load_wsgi
    self.wsgi = self.app.wsgi()
  File "/home/yamda/.virtualenvs/yamda_website/lib/python3.5/site-packages/gunicorn/app/base.py", line 67, in wsgi
    self.callable = self.load()
  File "/home/yamda/.virtualenvs/yamda_website/lib/python3.5/site-packages/gunicorn/app/wsgiapp.py", line 54, in load
    return self.load_wsgiapp()
  File "/home/yamda/.virtualenvs/yamda_website/lib/python3.5/site-packages/gunicorn/app/wsgiapp.py", line 43, in load_wsgiapp
    return util.import_app(self.app_uri)
  File "/home/yamda/.virtualenvs/yamda_website/lib/python3.5/site-packages/gunicorn/util.py", line 350, in import_app
    __import__(module)
ImportError: No module named 'yamda'
*****************
yamda.wsgi:application
[2018-06-15 11:54:52 +0000] [6131] [ERROR] Exception in worker process
Traceback (most recent call last):
  File "/home/yamda/.virtualenvs/yamda_website/lib/python3.5/site-packages/gunicorn/arbiter.py", line 583, in spawn_worker
    worker.init_process()
  File "/home/yamda/.virtualenvs/yamda_website/lib/python3.5/site-packages/gunicorn/workers/base.py", line 129, in init_process
    self.load_wsgi()
  File "/home/yamda/.virtualenvs/yamda_website/lib/python3.5/site-packages/gunicorn/workers/base.py", line 138, in load_wsgi
    self.wsgi = self.app.wsgi()
  File "/home/yamda/.virtualenvs/yamda_website/lib/python3.5/site-packages/gunicorn/app/base.py", line 67, in wsgi
    self.callable = self.load()
  File "/home/yamda/.virtualenvs/yamda_website/lib/python3.5/site-packages/gunicorn/app/wsgiapp.py", line 54, in load
    return self.load_wsgiapp()
  File "/home/yamda/.virtualenvs/yamda_website/lib/python3.5/site-packages/gunicorn/app/wsgiapp.py", line 43, in load_wsgiapp
    return util.import_app(self.app_uri)
  File "/home/yamda/.virtualenvs/yamda_website/lib/python3.5/site-packages/gunicorn/util.py", line 350, in import_app
    __import__(module)
ImportError: No module named 'yamda'
*****************
yamda.wsgi:application
Traceback (most recent call last):
  File "/home/yamda/.virtualenvs/yamda_website/lib/python3.5/site-packages/gunicorn/arbiter.py", line 203, in run
    self.manage_workers()
  File "/home/yamda/.virtualenvs/yamda_website/lib/python3.5/site-packages/gunicorn/arbiter.py", line 545, in manage_workers
    self.spawn_workers()
  File "/home/yamda/.virtualenvs/yamda_website/lib/python3.5/site-packages/gunicorn/arbiter.py", line 617, in spawn_workers
    time.sleep(0.1 * random.random())
  File "/home/yamda/.virtualenvs/yamda_website/lib/python3.5/site-packages/gunicorn/arbiter.py", line 245, in handle_chld
    self.reap_workers()
  File "/home/yamda/.virtualenvs/yamda_website/lib/python3.5/site-packages/gunicorn/arbiter.py", line 525, in reap_workers
    raise HaltServer(reason, self.WORKER_BOOT_ERROR)
gunicorn.errors.HaltServer: <HaltServer 'Worker failed to boot.' 3>

During handling of the above exception, another exception occurred:

Traceback (most recent call last):
  File "/home/yamda/.virtualenvs/yamda_website/bin/gunicorn", line 11, in <module>
    sys.exit(run())
  File "/home/yamda/.virtualenvs/yamda_website/lib/python3.5/site-packages/gunicorn/app/wsgiapp.py", line 63, in run
    WSGIApplication("%(prog)s [OPTIONS] [APP_MODULE]").run()
  File "/home/yamda/.virtualenvs/yamda_website/lib/python3.5/site-packages/gunicorn/app/base.py", line 223, in run
    super(Application, self).run()
  File "/home/yamda/.virtualenvs/yamda_website/lib/python3.5/site-packages/gunicorn/app/base.py", line 72, in run
    Arbiter(self).run()
  File "/home/yamda/.virtualenvs/yamda_website/lib/python3.5/site-packages/gunicorn/arbiter.py", line 232, in run
    self.halt(reason=inst.reason, exit_status=inst.exit_status)
  File "/home/yamda/.virtualenvs/yamda_website/lib/python3.5/site-packages/gunicorn/arbiter.py", line 345, in halt
    self.stop()
  File "/home/yamda/.virtualenvs/yamda_website/lib/python3.5/site-packages/gunicorn/arbiter.py", line 393, in stop
    time.sleep(0.1)
  File "/home/yamda/.virtualenvs/yamda_website/lib/python3.5/site-packages/gunicorn/arbiter.py", line 245, in handle_chld
    self.reap_workers()
  File "/home/yamda/.virtualenvs/yamda_website/lib/python3.5/site-packages/gunicorn/arbiter.py", line 525, in reap_workers
    raise HaltServer(reason, self.WORKER_BOOT_ERROR)
gunicorn.errors.HaltServer: <HaltServer 'Worker failed to boot.' 3>
/home/yamda/.virtualenvs/yamda_website/lib/python3.5/site-packages/psycopg2/__init__.py:144: UserWarning: The psycopg2 wheel package will be renamed from release 2.8; in order to keep installing from binary please use "pip install psycopg2-binary" instead. For details see: <http://initd.org/psycopg/docs/install.html#binary-install-from-pypi>.
  """)
*****************
yamda.wsgi:application
/home/yamda/.virtualenvs/yamda_website/lib/python3.5/site-packages/psycopg2/__init__.py:144: UserWarning: The psycopg2 wheel package will be renamed from release 2.8; in order to keep installing from binary please use "pip install psycopg2-binary" instead. For details see: <http://initd.org/psycopg/docs/install.html#binary-install-from-pypi>.
  """)
*****************
yamda.wsgi:application
/home/yamda/.virtualenvs/yamda_website/lib/python3.5/site-packages/psycopg2/__init__.py:144: UserWarning: The psycopg2 wheel package will be renamed from release 2.8; in order to keep installing from binary please use "pip install psycopg2-binary" instead. For details see: <http://initd.org/psycopg/docs/install.html#binary-install-from-pypi>.
  """)
*****************
yamda.wsgi:application
/home/yamda/.virtualenvs/yamda_website/lib/python3.5/site-packages/psycopg2/__init__.py:144: UserWarning: The psycopg2 wheel package will be renamed from release 2.8; in order to keep installing from binary please use "pip install psycopg2-binary" instead. For details see: <http://initd.org/psycopg/docs/install.html#binary-install-from-pypi>.
  """)
*****************
yamda.wsgi:application
/home/yamda/.virtualenvs/yamda_website/lib/python3.5/site-packages/psycopg2/__init__.py:144: UserWarning: The psycopg2 wheel package will be renamed from release 2.8; in order to keep installing from binary please use "pip install psycopg2-binary" instead. For details see: <http://initd.org/psycopg/docs/install.html#binary-install-from-pypi>.
  """)
*****************
yamda.wsgi:application
/home/yamda/.virtualenvs/yamda_website/lib/python3.5/site-packages/psycopg2/__init__.py:144: UserWarning: The psycopg2 wheel package will be renamed from release 2.8; in order to keep installing from binary please use "pip install psycopg2-binary" instead. For details see: <http://initd.org/psycopg/docs/install.html#binary-install-from-pypi>.
  """)
*****************
yamda.wsgi:application
/home/yamda/.virtualenvs/yamda_website/lib/python3.5/site-packages/psycopg2/__init__.py:144: UserWarning: The psycopg2 wheel package will be renamed from release 2.8; in order to keep installing from binary please use "pip install psycopg2-binary" instead. For details see: <http://initd.org/psycopg/docs/install.html#binary-install-from-pypi>.
  """)
*****************
yamda.wsgi:application
/home/yamda/.virtualenvs/yamda_website/lib/python3.5/site-packages/psycopg2/__init__.py:144: UserWarning: The psycopg2 wheel package will be renamed from release 2.8; in order to keep installing from binary please use "pip install psycopg2-binary" instead. For details see: <http://initd.org/psycopg/docs/install.html#binary-install-from-pypi>.
  """)
*****************
yamda.wsgi:application
/home/yamda/.virtualenvs/yamda_website/lib/python3.5/site-packages/psycopg2/__init__.py:144: UserWarning: The psycopg2 wheel package will be renamed from release 2.8; in order to keep installing from binary please use "pip install psycopg2-binary" instead. For details see: <http://initd.org/psycopg/docs/install.html#binary-install-from-pypi>.
  """)
*****************
yamda.wsgi:application
